Workbook

Sheet Asset with Warranty Expiration 
A1: ASSET NAME | B1: SITE CODE | C1: REGION | D1: MODEL | E1: LAST USER | F1: WARRANTY END DATE | G1: YEAR OF EXPIRATION | H1: USER DOMAIN | I1: IP ADDRESS | J1: MANUFACTURER | K1: DOMAIN | L1: SERIAL NUMBER | M1: STATE | N1: MAC ADDRESS | O1: OS
A2: TWMON045 | B2: MON | C2: AMER | D2: Latitude 5450 | E2: Eduardo.Rodriguez | F2: Tuesday, December 21, 2027 | G2: 2027 | H2: YOKOHAMA-TWS | I2: 10.58.249.46 | J2: Dell | K2: yokohama-tws.com | L2: JC5HN64 | M2: Active | N2: D0:C1:B5:7C:09:90 | O2: Windows 11 Enterprise Version 23H2
A3: TWSAKRHPV001 | B3: AKR | C3: AMER | D3: PowerEdge R340 | F3: Sunday, June 9, 2024 | G3: 2024 | I3: 10.57.211.19 | J3: Dell | K3: yokohama-tws | L3: 4KR08X2 | M3: Active | N3: 6C:2B:59:92:E6:02 | O3: Windows Server 2019 Standard (1809)
A4: TWSAKRL005 | B4: AKR | C4: AMER | D4: Latitude 5400 | F4: Monday, November 14, 2022 | G4: 2022 | I4: 192.168.1.159 | J4: Dell | K4: yokohama-tws | L4: GRDPXY2 | M4: Active | N4: 24:41:8C:4C:44:56 | O4: Windows 10 Enterprise Version 22H2
A5: TWSAKRL007 | B5: AKR | C5: AMER | D5: Latitude 5400 | E5: rob.liles | F5: Monday, November 14, 2022 | G5: 2022 | H5: YOKOHAMA-TWS | I5: 192.168.1.10 | J5: Dell | K5: yokohama-tws.com | L5: 587PXY2 | M5: Active | N5: 24:41:8C:4E:58:6D | O5: Windows 10 Enterprise Version 22H2
A6: TWSAKRL008 | B6: AKR | C6: AMER | D6: Latitude 7340 | E6: robert.brown | F6: Saturday, September 26, 2026 | G6: 2026 | H6: YOKOHAMA-TWS | I6: 192.168.1.66 | J6: Dell | K6: yokohama-tws | L6: HTGFJX3 | M6: Active | N6: 30:05:05:A7:51:25 | O6: Windows 10 Pro Version 22H2
A7: TWSAKRL011 | B7: AKR | C7: AMER | D7: Latitude 5400 | F7: Monday, November 14, 2022 | G7: 2022 | I7: 192.168.23.0 | J7: Dell | K7: yokohama-tws | L7: 987PXY2 | M7: Active | N7: 98:E7:43:E7:7F:E5 | O7: Windows 10 Enterprise Version 22H2
A8: TWSAKRL021 | B8: AKR | C8: AMER | D8: Latitude 5400 | E8: brian.edwards | F8: Wednesday, April 5, 2023 | G8: 2023 | H8: YOKOHAMA-TWS | I8: 192.168.27.109 | J8: Dell | K8: yokohama-tws | L8: B1WZ733 | M8: Active | N8: 74:D8:3E:B3:37:1F | O8: Windows 11 Enterprise Version 23H2
A9: TWSAKRL022 | B9: AKR | C9: AMER | D9: Latitude 5400 | F9: Wednesday, April 5, 2023 | G9: 2023 | I9: 192.168.1.254 | J9: Dell | K9: yokohama-tws | L9: 7XVZ733 | M9: Active | N9: 74:D8:3E:AD:3E:D2 | O9: Windows 10 Enterprise Version 22H2
A10: TWSAKRL023 | B10: AKR | C10: AMER | D10: Latitude 7320 | E10: ramsay.cabarcas | F10: Tuesday, November 5, 2024 | G10: 2024 | H10: YOKOHAMA-TWS | I10: 10.57.211.65 | J10: Dell | K10: yokohama-tws | L10: DTRG4J3 | M10: Active | N10: A0:29:19:AF:D7:E1 | O10: Windows 10 Enterprise Version 22H2
A11: TWSAKRL027 | B11: AKR | C11: AMER | D11: Latitude 5510 | E11: nickolas.bair | F11: Monday, April 29, 2024 | G11: 2024 | H11: YOKOHAMA-TWS | I11: 192.168.4.102 | J11: Dell | K11: yokohama-tws | L11: JZ2F3D3 | M11: Active | N11: F8:5E:A0:98:57:5B | O11: Windows 10 Pro Version 22H2
A12: TWSAKRL031 | B12: AKR | C12: AMER | D12: Latitude 5510 | F12: Monday, April 29, 2024 | G12: 2024 | I12: 192.168.1.167 | J12: Dell | K12: yokohama-tws | L12: F40M6D3 | M12: Active | N12: F8:5E:A0:B2:67:90 | O12: Windows 10 Enterprise Version 22H2
A13: TWSAKRL032 | B13: AKR | C13: AMER | D13: Latitude 7320 | E13: paige.sletzer | F13: Tuesday, November 5, 2024 | G13: 2024 | H13: YOKOHAMA-TWS | I13: 192.168.1.66 | J13: Dell | K13: yokohama-tws | L13: 965P5J3 | M13: Active | N13: 80:38:FB:A5:8F:A7 | O13: Windows 10 Enterprise Version 22H2
A14: TWSAKRL036 | B14: AKR | C14: AMER | D14: Precision 7560 | E14: Jeff.Miller | F14: Saturday, April 12, 2025 | G14: 2025 | H14: YOKOHAMA-TWS | I14: 192.168.33.15 | J14: Dell | K14: yokohama-tws | L14: 8W6PLN3 | M14: Active | N14: 08:92:04:63:A9:DE | O14: Windows 10 Pro Version 22H2
A15: TWSAKRL039 | B15: AKR | C15: AMER | D15: Precision 7560 | E15: Lance.Cole | F15: Saturday, April 12, 2025 | G15: 2025 | H15: YOKOHAMA-TWS | I15: 10.67.211.53 | J15: Dell | K15: yokohama-tws | L15: DHDPLN3 | M15: Active | N15: 2C:33:58:76:12:59 | O15: Windows 10 Pro Version 22H2
A16: TWSAKRL040 | B16: AKR | C16: AMER | D16: Latitude 7320 | E16: mark.surtel | F16: Tuesday, November 5, 2024 | G16: 2024 | H16: YOKOHAMA-TWS | I16: 192.168.68.115 | J16: Dell | K16: yokohama-tws | L16: 9JYG4J3 | M16: Active | N16: A0:29:19:AF:D7:EF | O16: Windows 10 Enterprise Version 22H2
A17: TWSAKRL047 | B17: AKR | C17: AMER | D17: Latitude 5400 | E17: brian.bentley | F17: Wednesday, April 5, 2023 | G17: 2023 | H17: YOKOHAMA-TWS | I17: 192.168.1.185 | J17: Dell | K17: yokohama-tws | L17: G1BM733 | M17: Active | N17: 74:D8:3E:B1:B1:65 | O17: Windows 11 Enterprise Version 23H2
A18: TWSAKRL048 | B18: AKR | C18: AMER | D18: Latitude 5400 | F18: Monday, November 14, 2022 | G18: 2022 | I18: 192.168.1.254 | J18: Dell | K18: yokohama-tws | L18: BY21YY2 | M18: Active | N18: 24:41:8C:4C:E3:25 | O18: Windows 10 Enterprise Version 22H2
A19: TWSAKRL053 | B19: AKR | C19: AMER | D19: Latitude 5590 | E19: denise.watson | F19: Saturday, August 27, 2022 | G19: 2022 | H19: YOKOHAMA-TWS | I19: 192.168.1.162 | J19: Dell | K19: yokohama-tws | L19: 2NCT0Z2 | M19: Active | N19: 98:E7:43:B2:AC:62 | O19: Windows 10 Enterprise Version 22H2
A20: TWSAKRL055 | B20: AKR | C20: AMER | D20: Precision 7670 | E20: zachary.pepper | F20: Saturday, October 25, 2025 | G20: 2025 | H20: YOKOHAMA-TWS | I20: 10.57.211.101 | J20: Dell | K20: yokohama-tws.com | L20: 6TMJ3T3 | M20: Active | N20: CC:96:E5:C5:7D:25 | O20: Windows 10 Enterprise Version 22H2
A21: TWSAKRL058 | B21: AKR | C21: AMER | D21: Latitude 7330 | E21: ashley.meadows | F21: Sunday, October 19, 2025 | G21: 2025 | H21: YOKOHAMA-TWS | I21: 10.67.211.67 | J21: Dell | K21: yokohama-tws | L21: 7T152T3 | M21: Active | N21: 3C:E9:F7:B5:5E:B9 | O21: Windows 10 Enterprise Version 22H2
A22: TWSAKRL061 | B22: AKR | C22: AMER | D22: Latitude 7490 | E22: briana.burgan | F22: Sunday, May 8, 2022 | G22: 2022 | H22: YOKOHAMA-TWS | I22: 10.57.211.80 | J22: Dell | K22: yokohama-tws | L22: HT4KQV2 | M22: Active | N22: 8C:04:BA:4E:E1:54 | O22: Windows 10 Enterprise Version 22H2
A23: TWSAKRL062 | B23: AKR | C23: AMER | D23: Latitude 7480 | E23: yamil.gonzalez | F23: Monday, November 23, 2020 | G23: 2020 | H23: YOKOHAMA-TWS | I23: 10.57.211.73 | J23: Dell | K23: yokohama-tws | L23: FG78PH2 | M23: Active | N23: A4:4C:C8:88:1B:75 | O23: Windows 10 Enterprise Version 22H2
A24: TWSAKRL401 | B24: AKR | C24: AMER | D24: Latitude 5440 | E24: kevin.mccallson | F24: Sunday, July 5, 2026 | G24: 2026 | H24: YOKOHAMA-TWS | I24: 192.168.125.183 | J24: Dell | K24: yokohama-tws | L24: 4PTV8Y3 | M24: Active | N24: F4:6D:3F:4E:BE:F2 | O24: Windows 10 Enterprise Version 22H2
A25: TWSAKRL402 | B25: AKR | C25: AMER | D25: Latitude 5440 | E25: dustin.hagestedt | F25: Sunday, July 5, 2026 | G25: 2026 | H25: YOKOHAMA-TWS | I25: 192.168.254.27 | J25: Dell | K25: yokohama-tws | L25: 6KTV8Y3 | M25: Active | N25: F4:6D:3F:4E:BF:29 | O25: Windows 10 Enterprise Version 22H2
A26: TWSAKRL403 | B26: AKR | C26: AMER | D26: Latitude 5440 | F26: Sunday, July 5, 2026 | G26: 2026 | I26: 10.57.211.78 | J26: Dell | K26: yokohama-tws | L26: 6ZXRBY3 | M26: Active | N26: AC:1A:3D:75:12:12 | O26: Windows 10 Pro Version 22H2
A27: TWSAKRL404 | B27: AKR | C27: AMER | D27: Latitude 5440 | E27: maddie.pere | F27: Sunday, July 5, 2026 | G27: 2026 | H27: YOKOHAMA-TWS | I27: 10.57.211.79 | J27: Dell | K27: yokohama-tws | L27: 38YRBY3 | M27: Active | N27: AC:19:8E:0B:AA:54 | O27: Windows 10 Pro Version 22H2
A28: TWSAKRL406 | B28: AKR | C28: AMER | D28: Latitude 5440 | E28: stacy.price | F28: Sunday, July 5, 2026 | G28: 2026 | H28: YOKOHAMA-TWS | I28: 10.57.211.58 | J28: Dell | K28: yokohama-tws | L28: CQRRBY3 | M28: Active | N28: AC:91:A1:A9:6A:6D | O28: Windows 10 Enterprise Version 22H2
A29: TWSAKRL407 | B29: AKR | C29: AMER | D29: Latitude 7480 | E29: julio.ortiz | F29: Sunday, June 21, 2020 | G29: 2020 | H29: YOKOHAMA-TWS | I29: 172.16.40.51 | J29: Dell | K29: yokohama-tws | L29: GN676H2 | M29: Active | N29: D4:81:D7:E0:29:66 | O29: Windows 10 Enterprise Version 22H2
A30: TWSAKRL408 | B30: AKR | C30: AMER | D30: Latitude 5440 | E30: ben.spooner | F30: Wednesday, July 22, 2026 | G30: 2026 | H30: YOKOHAMA-TWS | I30: 192.168.1.46 | J30: Dell | K30: yokohama-tws | L30: B2J59Y3 | M30: Active | N30: F4:3B:D8:02:66:C4 | O30: Windows 10 Pro Version 22H2
A31: TWSAKRL409 | B31: AKR | C31: AMER | D31: Latitude 5440 | E31: kaitlin.switzer | F31: Wednesday, July 22, 2026 | G31: 2026 | H31: YOKOHAMA-TWS | I31: 192.168.1.157 | J31: Dell | K31: yokohama-tws | L31: JR0LCY3 | M31: Active | N31: F4:3B:D8:13:F5:1F | O31: Windows 10 Enterprise Version 22H2
A32: TWSAKRL411 | B32: AKR | C32: AMER | D32: Precision 7670 | F32: Saturday, August 29, 2026 | G32: 2026 | I32: 192.168.50.110 | J32: Dell | K32: yokohama-tws | L32: GCLJDY3 | M32: Active | N32: B0:DC:EF:A9:0E:16 | O32: Windows 10 Enterprise Version 22H2
A33: TWSAKRL412 | B33: AKR | C33: AMER | D33: Latitude 7320 | E33: nick.hunt | F33: Tuesday, November 5, 2024 | G33: 2024 | H33: YOKOHAMA-TWS | I33: 192.168.4.25 | J33: Dell | K33: yokohama-tws | L33: D7VG4J3 | M33: Active | N33: 80:38:FB:A5:8F:2A | O33: Windows 10 Enterprise Version 22H2
A34: TWSAKRL415 | B34: AKR | C34: AMER | D34: Latitude 5440 | E34: erik.dewitz | F34: Wednesday, July 22, 2026 | G34: 2026 | H34: YOKOHAMA-TWS | I34: 192.168.1.194 | J34: Dell | K34: yokohama-tws.com | L34: 95J59Y3 | M34: Active | N34: F4:3B:D8:02:57:0B | O34: Windows 10 Enterprise Version 22H2
A35: TWSAKRL416 | B35: AKR | C35: AMER | D35: Latitude 5440 | E35: tyler.money | F35: Sunday, July 5, 2026 | G35: 2026 | H35: YOKOHAMA-TWS | I35: 10.67.211.77 | J35: Dell | K35: yokohama-tws | L35: 6DLT8Y3 | M35: Active | N35: AC:19:8E:08:DF:40 | O35: Windows 10 Enterprise Version 22H2
A36: TWSAKRL417 | B36: AKR | C36: AMER | D36: Precision 7670 | E36: ted.migdal | F36: Saturday, October 25, 2025 | G36: 2025 | H36: YOKOHAMA-TWS | I36: 192.168.0.165 | J36: Dell | K36: yokohama-tws | L36: 5PWK3T3 | M36: Active | N36: F4:CE:23:B5:92:94 | O36: Windows 10 Enterprise Version 22H2
A37: TWSAKRL418 | B37: AKR | C37: AMER | D37: Latitude 5400 | E37: nuzhah.peerally | F37: Saturday, October 1, 2022 | G37: 2022 | H37: YOKOHAMA-TWS | I37: 192.168.2.24 | J37: Dell | K37: yokohama-tws | L37: 1WBD0Z2 | M37: Active | N37: 50:EB:71:E6:F2:9E | O37: Windows 10 Enterprise Version 22H2
A38: TWSAKRL419 | B38: AKR | C38: AMER | D38: Latitude 5510 | E38: clarence.warren | F38: Monday, April 29, 2024 | G38: 2024 | H38: YOKOHAMA-TWS | I38: 10.57.211.66 | J38: Dell | K38: yokohama-tws | L38: DB0H7D3 | M38: Active | N38: 38:14:28:17:0E:40 | O38: Windows 10 Enterprise Version 22H2
A39: TWSAKRL420 | B39: AKR | C39: AMER | D39: Latitude 5440 | E39: shane.kennedy | F39: Wednesday, January 27, 2027 | G39: 2027 | H39: YOKOHAMA-TWS | I39: 10.57.211.99 | J39: Dell | K39: yokohama-tws | L39: F51XVW3 | M39: Active | N39: 4C:D7:17:E5:E8:94 | O39: Windows 10 Enterprise Version 22H2
A40: TWSAKRL421 | B40: AKR | C40: AMER | D40: Latitude 5440 | E40: Stephanie.Hughes | F40: Sunday, July 5, 2026 | G40: 2026 | H40: YOKOHAMA-TWS | I40: 192.168.0.41 | J40: Dell | K40: yokohama-tws | L40: 9KTV8Y3 | M40: Active | N40: AC:1A:3D:75:11:F7 | O40: Windows 10 Enterprise Version 22H2
...

Sheet List3
A1: DeviceName | B1: ManagedBy | C1: Manufacturer | D1: Model | E1: OSVersion | F1: UpgradeEligibility | G1: Windows
A2: TCSKRAL032 | B2: mdm/mmpc | C2: Dell Inc. | D2: Latitude 5590 | E2: 10.0.19045.5965 | F2: Capable | G2: 10 | H2: =VLOOKUP(A2,'Asset with Warranty Expiration '!$1:$1048576,5,FALSE) -> Bostjan.Novak
A3: TCSKRAL130 | B3: mdm/mmpc | C3: Dell Inc. | D3: Latitude 5400 | E3: 10.0.19045.5965 | F3: Capable | G3: 10 | H3: =VLOOKUP(A3,'Asset with Warranty Expiration '!$1:$1048576,5,FALSE) -> Damjan.Dolinsek
A4: TCSKRAL131 | B4: mdm/mmpc | C4: Dell Inc. | D4: Latitude 5500 | E4: 10.0.19045.5965 | F4: Capable | G4: 10 | H4: =VLOOKUP(A4,'Asset with Warranty Expiration '!$1:$1048576,5,FALSE) -> Miodrag.Ristic
A5: TCSKRAL143 | B5: mdm/mmpc | C5: Dell Inc. | D5: Latitude 5510 | E5: 10.0.19045.5854 | F5: Capable | G5: 10 | H5: =VLOOKUP(A5,'Asset with Warranty Expiration '!$1:$1048576,5,FALSE) -> Mateja.Burgar
A6: TCSKRAL154 | B6: mdm/mmpc | C6: Dell Inc. | D6: Latitude 3510 | E6: 10.0.19045.5965 | F6: Capable | G6: 10 | H6: =VLOOKUP(A6,'Asset with Warranty Expiration '!$1:$1048576,5,FALSE) -> petra.praprotnik
A7: TCSKRAL155 | B7: mdm/mmpc | C7: Dell Inc. | D7: Latitude 3510 | E7: 10.0.19045.5965 | F7: Capable | G7: 10 | H7: =VLOOKUP(A7,'Asset with Warranty Expiration '!$1:$1048576,5,FALSE) -> marjeta.dolinsek
A8: TCSKRAL162 | B8: mdm/mmpc | C8: Dell Inc. | D8: Latitude 5510 | E8: 10.0.19045.5965 | F8: Capable | G8: 10 | H8: =VLOOKUP(A8,'Asset with Warranty Expiration '!$1:$1048576,5,FALSE) -> Tajda.Brlogar
A9: TCSKRAL170 | B9: mdm/mmpc | C9: Dell Inc. | D9: Latitude 5510 | E9: 10.0.19045.5965 | F9: Capable | G9: 10 | H9: =VLOOKUP(A9,'Asset with Warranty Expiration '!$1:$1048576,5,FALSE) -> Marjan.Trobec
A10: TCSKRAL172 | B10: mdm/mmpc | C10: Dell Inc. | D10: Latitude 5510 | E10: 10.0.19045.5965 | F10: Capable | G10: 10 | H10: =VLOOKUP(A10,'Asset with Warranty Expiration '!$1:$1048576,5,FALSE) -> Zan.Rupar
A11: TCSKRAL189 | B11: mdm/mmpc | C11: Dell Inc. | D11: Precision 7560 | E11: 10.0.19045.5965 | F11: Capable | G11: 10 | H11: =VLOOKUP(A11,'Asset with Warranty Expiration '!$1:$1048576,5,FALSE) -> 0
A12: TCSKRAL191 | B12: mdm/mmpc | C12: Dell Inc. | D12: Latitude 5520 | E12: 10.0.19045.5965 | F12: Capable | G12: 10 | H12: =VLOOKUP(A12,'Asset with Warranty Expiration '!$1:$1048576,5,FALSE) -> Anze.Pintar
A13: TCSKRAW024 | B13: mdm/mmpc | C13: Dell Inc. | D13: OptiPlex 7060 | E13: 10.0.19045.5965 | F13: Capable | G13: 10 | H13: =VLOOKUP(A13,'Asset with Warranty Expiration '!$1:$1048576,5,FALSE) -> Damjan.Komic
... A1206: YTWSAM-WAKL569 | B1206: mdm/mmpc | C1206: Dell Inc. | D1206: Latitude 5440 | E1206: 10.0.19045.5737 | F1206: Capable | G1206: 10 | H1206: =VLOOKUP(A1206,'Asset with Warranty Expiration '!$1:$1048576,5,FALSE) -> #N/A

Sheet OTR
A1: Nome PC | B1: LAST USER | C1: SERIAL NUMBER | D1: Year | E1: Quarter | F1: Month | G1: Day | H1: MODEL
A2: TWSOTRL001 | B2: bohumil.vrba | C2: 67FL0J3 | D2: 2024 | E2: Qtr 4 | F2: October | G2: 18 | H2: Latitude 5420 | I2: #N/A
A3: TWSOTRL002 | B3: Petr.Skopec | C3: 1N8WM72 | D3: 2021 | E3: Qtr 1 | F3: March | G3: 11 | H3: Latitude E7450 | I3: #N/A
A4: TWSOTRL003 | B4: jiri.kotasek | C4: CR4FKG3 | D4: 2024 | E4: Qtr 4 | F4: November | G4: 10 | H4: Latitude 3520 | I4: Capable
A5: TWSOTRL012 | B5: Vladimir.Jurcik | C5: D3FZ7Y2 | D5: 2022 | E5: Qtr 3 | F5: July | G5: 30 | H5: Latitude 5590 | I5: Capable
A6: TWSOTRL013 | B6: Helena.Buresova | C6: JS2YN73 | D6: 2023 | E6: Qtr 4 | F6: November | G6: 28 | H6: Latitude 5410 | I6: Capable
A7: TWSOTRL015 | B7: petr.bar | C7: HN8Z7Y2 | D7: 2022 | E7: Qtr 3 | F7: July | G7: 30 | H7: Latitude 5590 | I7: Capable
A8: TWSOTRL017 | B8: tomas.istvanek | C8: H7364M2 | D8: 2020 | E8: Qtr 4 | F8: December | G8: 16 | H8: Latitude 5580 | I8: #N/A
A9: TWSOTRL018 | B9: Renata.Kovalova | C9: FCDB533 | D9: 2023 | E9: Qtr 2 | F9: April | G9: 25 | H9: Latitude 5400 | I9: Capable
A10: TWSOTRL028 | B10: david.navratil | C10: 4BFF3B3 | D10: 2024 | E10: Qtr 3 | F10: July | G10: 24 | H10: Latitude 5520 | I10: Capable
A11: TWSOTRL030 | B11: Marie.Lubinkova | C11: 3WGBT93 | D11: 2024 | E11: Qtr 2 | F11: June | G11: 3 | H11: Latitude 3410 | I11: #N/A
A12: TWSOTRL033 | B12: Petra.Drizgova | C12: 2WGBT93 | D12: 2024 | E12: Qtr 2 | F12: June | G12: 3 | H12: Latitude 3410 | I12: Capable
A13: TWSOTRL038 | B13: Jiri.Manasek | C13: FST53F3 | D13: 2024 | E13: Qtr 3 | F13: July | G13: 28 | H13: Latitude 5420 | I13: Capable
A14: TWSOTRL039 | B14: michal.navratil | C14: 8BFF3B3 | D14: 2024 | E14: Qtr 3 | F14: July | G14: 26 | H14: Latitude 5520 | I14: Capable
A15: TWSOTRL040 | B15: Alice.Konarikova | C15: 3V98K32 | D15: 2019 | E15: Qtr 4 | F15: December | G15: 24 | H15: Latitude E5540 | I15: #N/A
A16: TWSOTRL041 | B16: Katerina.Novotna | C16: HMVX633 | D16: 2023 | E16: Qtr 2 | F16: April | G16: 4 | H16: Latitude 5400 | I16: Capable
A17: TWSOTRL042 | B17: Roman.Bata | C17: 6B21733 | D17: 2023 | E17: Qtr 2 | F17: April | G17: 9 | H17: Latitude 5500 | I17: Capable
A18: TWSOTRL043 | B18: Lenka.Vitova | C18: 4WGBT93 | D18: 2024 | E18: Qtr 2 | F18: June | G18: 3 | H18: Latitude 3410 | I18: Capable
A19: TWSOTRL044 | B19: David.Hodon | C19: JV41NF2 | D19: 2022 | E19: Qtr 1 | F19: February | G19: 18 | H19: Latitude 7490 | I19: Capable
A20: TWSOTRL046 | B20: Josef.Kremecek | C20: 6B0J693 | D20: 2023 | E20: Qtr 4 | F20: December | G20: 6 | H20: Latitude 7410 | I20: Capable
A21: TWSOTRL047 | B21: Jaroslav.Orlik | C21: C1PGTQ2 | D21: 2021 | E21: Qtr 3 | F21: September | G21: 10 | H21: Precision 7520 | I21: #N/A
A22: TWSOTRL048 | B22: Pavel.Mikeska | C22: CZJJP73 | D22: 2023 | E22: Qtr 4 | F22: December | G22: 1 | H22: Latitude 5510 | I22: Capable
A23: TWSOTRL049 | B23: Tomas.Machura | C23: 6G9TFB3 | D23: 2024 | E23: Qtr 1 | F23: February | G23: 1 | H23: Latitude 5410 | I23: Capable
A24: TWSOTRL051 | B24: David.Warzel | C24: 5L71JR2 | D24: 2021 | E24: Qtr 4 | F24: October | G24: 27 | H24: Precision 5530 | I24: Capable
A25: TWSOTRL052 | B25: Michal.Aliger | C25: 1J189C3 | D25: 2024 | E25: Qtr 1 | F25: March | G25: 5 | H25: Latitude 5410 | I25: Capable
A26: TWSOTRL056 | B26: Zbynek.Holasek | C26: 97KJ693 | D26: 2023 | E26: Qtr 4 | F26: December | G26: 5 | H26: Precision 7550 | I26: Capable
A27: TWSOTRW099 | B27: TWS.OTR.GSERVIS | C27: 4DD1842 | D27: 2019 | E27: Qtr 4 | F27: December | G27: 20 | H27: OptiPlex 9020 | I27: #N/A
A28: TWSOTRW103 | B28: Miroslav.Gryga | C28: 3TJW5K2 | D28: 2021 | E28: Qtr 2 | F28: May | G28: 15 | H28: OptiPlex 7040 | I28: #N/A
A29: TWSOTRW108 | B29: Roman.Hora | C29: 60V4K03 | D29: 2023 | E29: Qtr 4 | F29: November | G29: 5 | H29: OptiPlex 7070 | I29: Capable
A30: TWSOTRW109 | B30: tws.otr.grading.ct | C30: FGPB642 | D30: 2019 | E30: Qtr 4 | F30: December | G30: 17 | H30: OptiPlex 9020 | I30: #N/A
A31: TWSOTRW111 | B31: TWS.OTR.Lobby1 | C31: C2VVKQ2 | D31: 2022 | E31: Qtr 3 | F31: July | G31: 3 | H31: OptiPlex 7050 | I31: #N/A
A32: TWSOTRW112 | C32: C2WVKQ2 | D32: 2022 | E32: Qtr 3 | F32: July | G32: 3 | H32: OptiPlex 7050 | I32: #N/A
A33: TWSOTRW117 | B33: miroslav.brezina | C33: 3TJP5K2 | D33: 2021 | E33: Qtr 2 | F33: May | G33: 15 | H33: OptiPlex 7040 | I33: #N/A
A34: TWSOTRW119 | B34: Katerina.Vecerova | C34: 3TLN5K2 | D34: 2021 | E34: Qtr 2 | F34: May | G34: 15 | H34: OptiPlex 7040 | I34: #N/A
A35: TWSOTRW130 | B35: TWS.OTR.PRIJEM12.1 | C35: 98D1842 | D35: 2019 | E35: Qtr 4 | F35: December | G35: 20 | H35: OptiPlex 9020 | I35: #N/A
A36: TWSOTRW132 | B36: Pavel.Kocian | C36: J1TDC72 | D36: 2021 | E36: Qtr 3 | F36: July | G36: 26 | H36: OptiPlex 7040 | I36: #N/A
A37: TWSOTRW133 | B37: martin.hyncica | C37: 3TLV5K2 | D37: 2021 | E37: Qtr 2 | F37: May | G37: 15 | H37: OptiPlex 7040 | I37: #N/A
A38: TWSOTRW142 | B38: TWS.OTR.SOGOS | C38: HVC1842 | D38: 2019 | E38: Qtr 4 | F38: December | G38: 20 | H38: OptiPlex 9020 | I38: #N/A
A39: TWSOTRW143 | B39: michal.sevcik | C39: 3TQR5K2 | D39: 2021 | E39: Qtr 2 | F39: May | G39: 15 | H39: OptiPlex 7040 | I39: #N/A
A40: TWSOTRW144 | B40: TWS.OTR.AgroOdborari | C40: 596XF82 | D40: 2020 | E40: Qtr 4 | F40: October | G40: 12 | H40: OptiPlex 9020 | I40: #N/A
...

Sheet PRG
A1: TWSPRAL020 | B1: mdm/mmpc | C1: Dell Inc. | D1: Latitude 7390 | E1: 10.0.19045.5854 | F1: Capable | G1: 10 | H1: Yavor.Yanchev
A2: TWSPRAL022 | B2: mdm/mmpc | C2: Dell Inc. | D2: Latitude 7390 | E2: 10.0.19045.5854 | F2: Capable | G2: 10 | H2: daniel.senkyr
A3: TWSPRAL026 | B3: mdm/mmpc | C3: Dell Inc. | D3: Latitude 7390 | E3: 10.0.19045.5854 | F3: Capable | G3: 10 | H3: roman.jiracek
A4: TWSPRALDP7G7S3 | B4: mdm/mmpc | C4: Dell Inc. | D4: Latitude 5530 | E4: 10.0.19045.5854 | F4: Capable | G4: 10 | H4: Eliska.Lacinova
A5: TWSPRGL004 | B5: mdm/mmpc | C5: Dell Inc. | D5: Latitude 5510 | E5: 10.0.19045.5854 | F5: Capable | G5: 10 | H5: tomas.pavlicek
A6: TWSPRGL009 | B6: mdm/mmpc | C6: Dell Inc. | D6: Latitude 5420 | E6: 10.0.19045.5854 | F6: Capable | G6: 10 | H6: Kumara.Botheju
A7: TWSPRGL013 | B7: mdm/mmpc | C7: Dell Inc. | D7: Latitude 5590 | E7: 10.0.19045.5854 | F7: Capable | G7: 10 | H7: Radek.Lanka
A8: TWSPRGL023 | B8: mdm/mmpc | C8: Dell Inc. | D8: Latitude 7490 | E8: 10.0.19045.5854 | F8: Capable | G8: 10 | H8: Jan.Zima
A9: TWSPRGL032 | B9: mdm/mmpc | C9: Dell Inc. | D9: Latitude 7400 | E9: 10.0.19045.5854 | F9: Capable | G9: 10 | H9: Radek.Cmunt
A10: TWSPRGL070 | B10: mdm/mmpc | C10: Dell Inc. | D10: Precision 7530 | E10: 10.0.19045.5854 | F10: Capable | G10: 10 | H10: Jan.Masek
A11: TWSPRGL075 | B11: mdm/mmpc | C11: Dell Inc. | D11: Latitude 7490 | E11: 10.0.19045.5854 | F11: Capable | G11: 10 | H11: jitka.vondrackova
A12: TWSPRGL082 | B12: mdm/mmpc | C12: Dell Inc. | D12: Latitude 5400 | E12: 10.0.19045.5854 | F12: Capable | G12: 10 | H12: alena.safarova
... A61: TWSPRGLHD5J414 | B61: mdm/mmpc | C61: Dell Inc. | D61: Latitude 7440 | E61: 10.0.19045.5854 | F61: Capable | G61: 10 | H61: vlad.tudose
A62: TWSPRGLHSYDGS3 | B62: mdm/mmpc | C62: Dell Inc. | D62: Latitude 5530 | E62: 10.0.19045.5854 | F62: Capable | G62: 10 | H62: #N/A
A63: TWSPRGLJFHCVT3 | B63: mdm/mmpc | C63: Dell Inc. | D63: Latitude 5430 | E63: 10.0.19045.5854 | F63: Capable | G63: 10 | H63: Marian.Tichy
A64: TWSPRGW013 | B64: mdm/mmpc | C64: Dell Inc. | D64: OptiPlex 7070 | E64: 10.0.19045.5854 | F64: Capable | G64: 10 | H64: TWS.PRG.KontrolaV
A65: TWSPRGW043 | B65: mdm/mmpc | C65: Dell Inc. | D65: OptiPlex 7070 | E65: 10.0.19045.5854 | F65: Capable | G65: 10 | H65: Markéta Ziková

Sheet ZLS
A1: TWSZLSL003 | B1: mdm/mmpc | C1: Dell Inc. | D1: Latitude 5510 | E1: 10.0.19045.5854 | F1: Capable | G1: 10 | H1: Petr.Hustak
A2: TWSZLSL004 | B2: mdm/mmpc | C2: Dell Inc. | D2: Latitude 5590 | E2: 10.0.19045.5854 | F2: Capable | G2: 10 | H2: Jana.Chudarkova
A3: TWSZLSL007 | B3: mdm/mmpc | C3: Dell Inc. | D3: Latitude 5420 | E3: 10.0.19045.5854 | F3: Capable | G3: 10 | H3: ladislav.kolek
A4: TWSZLSL009 | B4: mdm/mmpc | C4: Dell Inc. | D4: Latitude 3510 | E4: 10.0.19045.5737 | F4: Capable | G4: 10 | H4: 0
A5: TWSZLSL014 | B5: mdm/mmpc | C5: Dell Inc. | D5: Latitude 5520 | E5: 10.0.19045.5854 | F5: Capable | G5: 10 | H5: Zdenek.Mlynek
A6: TWSZLSL015 | B6: mdm/mmpc | C6: Dell Inc. | D6: Latitude 7420 | E6: 10.0.19045.5854 | F6: Capable | G6: 10 | H6: Petra.Brankova
A7: TWSZLSL017 | B7: mdm/mmpc | C7: Dell Inc. | D7: Latitude 7320 | E7: 10.0.19045.5854 | F7: Capable | G7: 10 | H7: Karel.Stefek
A8: TWSZLSL018 | B8: mdm/mmpc | C8: Dell Inc. | D8: Precision 7670 | E8: 10.0.19045.5854 | F8: Capable | G8: 10 | H8: rahul.gaikar
A9: TWSZLSL019 | B9: mdm/mmpc | C9: Dell Inc. | D9: Latitude 5430 | E9: 10.0.19045.5854 | F9: Capable | G9: 10 | H9: anilkumar.singh
A10: TWSZLSL023 | B10: mdm/mmpc | C10: Dell Inc. | D10: Precision 7550 | E10: 10.0.19045.5854 | F10: Capable | G10: 10 | H10: Dusan.Slezak
A11: TWSZLSL034 | B11: mdm/mmpc | C11: Dell Inc. | D11: Latitude 5590 | E11: 10.0.19045.5854 | F11: Capable | G11: 10 | H11: Pavel.Holik
A12: TWSZLSL071 | B12: mdm/mmpc | C12: Dell Inc. | D12: Precision 7670 | E12: 10.0.19045.5854 | F12: Capable | G12: 10 | H12: Jaroslav.Stastny
A13: TWSZLSL072 | B13: mdm/mmpc | C13: Dell Inc. | D13: Latitude 5530 | E13: 10.0.19045.5854 | F13: Capable | G13: 10 | H13: Martin.Betik
A14: TWSZLSL089 | B14: mdm/mmpc | C14: Dell Inc. | D14: Latitude 5590 | E14: 10.0.19045.5854 | F14: Capable | G14: 10 | H14: Vlastimil.Fryzelka
A15: TWSZLSL119 | B15: mdm/mmpc | C15: Dell Inc. | D15: Latitude 5500 | E15: 10.0.19045.5854 | F15: Capable | G15: 10 | H15: Petr.Jurak
A16: TWSZLSL120 | B16: mdm/mmpc | C16: Dell Inc. | D16: Latitude 5500 | E16: 10.0.19045.5854 | F16: Capable | G16: 10 | H16: Svatava.Hemmelova
... A23: TWSZLSL809NPX3 | B23: mdm/mmpc | C23: Dell Inc. | D23: Latitude 5540 | E23: 10.0.19045.5854 | F23: Capable | G23: 10 | H23: Jan.Kledrowetz
A24: TWSZLSL8DSKCY3 | B24: mdm/mmpc | C24: Dell Inc. | D24: Precision 7680 | E24: 10.0.19045.5854 | F24: Capable | G24: 10 | H24: 0
A25: TWSZLSL8Q9RR04 | B25: mdm/mmpc | C25: Dell Inc. | D25: Precision 7680 | E25: 10.0.19045.5854 | F25: Capable | G25: 10 | H25: Michal.Vana
A26: TWSZLSL909NPX3 | B26: mdm/mmpc | C26: Dell Inc. | D26: Latitude 5540 | E26: 10.0.19045.5854 | F26: Capable | G26: 10 | H26: vojtech.klis
A27: TWSZLSL9CDX7S3 | B27: mdm/mmpc | C27: Dell Inc. | D27: Latitude 5530 | E27: 10.0.19045.5854 | F27: Capable | G27: 10 | H27: Josef.Kubanik
A28: TWSZLSLBCDX7S3 | B28: mdm/mmpc | C28: Dell Inc. | D28: Latitude 5530 | E28: 10.0.19045.5854 | F28: Capable | G28: 10 | H28: Vitezslav.Kremecek
A29: TWSZLSLBTPYJS3 | B29: mdm/mmpc | C29: Dell Inc. | D29: Latitude 5540 | E29: 10.0.19045.5854 | F29: Capable | G29: 10 | H29: Sona.Stravova
A30: TWSZLSLCTPYJS3 | B30: mdm/mmpc | C30: Dell Inc. | D30: Latitude 5540 | E30: 10.0.19045.5854 | F30: Capable | G30: 10 | H30: Petr.Valuch
A31: TWSZLSLFWPG814 | B31: mdm/mmpc | C31: Dell Inc. | D31: Precision 7680 | E31: 10.0.19045.5854 | F31: Capable | G31: 10 | H31: Pavel.Urban
A32: TWSZLSLH0VL5M3 | B32: mdm/mmpc | C32: Dell Inc. | D32: Latitude 5420 | E32: 10.0.19045.5854 | F32: Capable | G32: 10 | H32: veronika.tomkova
A33: TWSZLSLJ2SW7S3 | B33: mdm/mmpc | C33: Dell Inc. | D33: Latitude 5530 | E33: 10.0.19045.5854 | F33: Capable | G33: 10 | H33: 0
A34: TWSZLSLJVGVFY3 | B34: mdm/mmpc | C34: Dell Inc. | D34: Precision 7680 | E34: 10.0.19045.5854 | F34: Capable | G34: 10 | H34: Petr.Nedbal
A35: TWSZLSW054 | B35: mdm/mmpc | C35: Dell Inc. | D35: OptiPlex 7000 | E35: 10.0.19045.5854 | F35: Capable | G35: 10 | H35: petr.sopik
A36: TWSZLSW064 | B36: mdm/mmpc | C36: Dell Inc. | D36: OptiPlex 7080 | E36: 10.0.19045.5854 | F36: Capable | G36: 10 | H36: TWS.ZLS.AL
A37: TWSZLSW071 | B37: mdm/mmpc | C37: Dell Inc. | D37: Precision 5820 Tower | E37: 10.0.19045.5854 | F37: Capable | G37: 10 | H37: vojtech.klis
A38: TWSZLSW072 | B38: mdm/mmpc | C38: Dell Inc. | D38: Precision 5820 Tower | E38: 10.0.19045.5854 | F38: Capable | G38: 10 | H38: anilkumar.singh
A39: TWSZLSW159 | B39: mdm/mmpc | C39: Dell Inc. | D39: Precision 5820 Tower | E39: 10.0.19045.5854 | F39: Capable | G39: 10 | H39: Jan.Kledrowetz
A40: TWSZLSW161 | B40: mdm/mmpc | C40: Dell Inc. | D40: OptiPlex 7080 | E40: 10.0.19045.5854 | F40: Capable | G40: 10 | H40: TWS.ZLS.MDR2
A41: TWSZLSW162 | B41: mdm/mmpc | C41: Dell Inc. | D41: OptiPlex 7080 | E41: 10.0.19045.5854 | F41: Capable | G41: 10 | H41: TWS.ZLS.MDR3
A42: TWSZLSW163 | B42: mdm/mmpc | C42: Dell Inc. | D42: OptiPlex 7080 | E42: 10.0.19045.5854 | F42: Capable | G42: 10 | H42: TWS.ZLS.Mooney2
A43: TWSZLSW165 | B43: mdm/mmpc | C43: Dell Inc. | D43: OptiPlex 7080 | E43: 10.0.19045.5854 | F43: Capable | G43: 10 | H43: TWS.ZLS.MDR4
A44: TWSZLSW166 | B44: mdm/mmpc | C44: Dell Inc. | D44: OptiPlex 7080 | E44: 10.0.19045.5854 | F44: Capable | G44: 10 | H44: TWS.ZLS.Mooney3
A45: TWSZLSWFYM7Q14 | B45: mdm/mmpc | C45: Dell Inc. | D45: OptiPlex Micro 7010 | E45: 10.0.19045.5854 | F45: Capable | G45: 10 | H45: TWS.ZLS.AL
A46: TWSZLSWGYM7Q14 | B46: mdm/mmpc | C46: Dell Inc. | D46: OptiPlex Micro 7010 | E46: 10.0.19045.5854 | F46: Capable | G46: 10 | H46: Jirina.Klabackova

Sheet LOZ
A1: TISLOZL022 | B1: mdm/mmpc | C1: Dell Inc. | D1: Latitude 5520 | E1: 10.0.19045.5965 | F1: Capable | G1: 10 | H1: natalia.pietruszka
A2: TISLOZL088 | B2: mdm/mmpc | C2: Dell Inc. | D2: Latitude 5540 | E2: 10.0.19045.5854 | F2: Capable | G2: 10 | H2: Tomasz.Glanc
A3: TISLOZL1ZJTKN3 | B3: mdm/mmpc | C3: Dell Inc. | D3: Latitude 5420 | E3: 10.0.19045.5965 | F3: Capable | G3: 10 | H3: Krzysztof.Swiech
A4: TISLOZL62N5DK3 | B4: mdm/mmpc | C4: Dell Inc. | D4: Latitude 5430 | E4: 10.0.19045.5965 | F4: Capable | G4: 10 | H4: Artur.Skrabski
A5: TISLOZL666 | B5: mdm/mmpc | C5: Dell Inc. | D5: Latitude 5430 | E5: 10.0.19045.5965 | F5: Capable | G5: 10 | H5: Filip.Skrzypkowski
A6: TISLOZL6ZQ4GS3 | B6: mdm/mmpc | C6: Dell Inc. | D6: Latitude 5530 | E6: 10.0.19045.5965 | F6: Capable | G6: 10 | H6: joanna.dunaj
A7: TISLOZLCNZ8PL3 | B7: mdm/mmpc | C7: Dell Inc. | D7: Latitude 5520 | E7: 10.0.19045.5965 | F7: Capable | G7: 10 | H7: damian.jozefiak
A8: TISLOZLDNZ8PL3 | B8: mdm/mmpc | C8: Dell Inc. | D8: Latitude 5520 | E8: 10.0.19045.5965 | F8: Capable | G8: 10 | H8: Katarzyna.Pajszczyk
A9: TISLOZLHQ0RCK3 | B9: mdm/mmpc | C9: Dell Inc. | D9: Latitude 7330 | E9: 10.0.19045.5965 | F9: Capable | G9: 10 | H9: miroslaw.tomaszewski
A10: TWSLOZL003 | B10: mdm/mmpc | C10: Dell Inc. | D10: Latitude 5520 | E10: 10.0.19045.5854 | F10: Capable | G10: 10 | H10: patryk.zaremba
A11: TWSLOZL024 | B11: mdm/mmpc | C11: Dell Inc. | D11: Latitude 5420 | E11: 10.0.19045.5854 | F11: Capable | G11: 10 | H11: Witold.Walas
A12: TWSLOZL030 | B12: mdm/mmpc | C12: Dell Inc. | D12: Latitude 5420 | E12: 10.0.19045.5854 | F12: Capable | G12: 10 | H12: ireneusz.cacala
... A20: TWSLOZLHQWB5X3 | B20: mdm/mmpc | C20: Dell Inc. | D20: Latitude 5430 | E20: 10.0.19045.5854 | F20: Capable | G20: 10 | H20: Emilia.Pruban

Sheet ERB
A1: TWSERBL003 | B1: mdm/mmpc | C1: Dell Inc. | D1: Latitude 5590 | E1: 10.0.19045.5854 | F1: Capable | G1: 10 | H1: Roland.Winkler
A2: TWSERBL006 | B2: mdm/mmpc | C2: Dell Inc. | D2: Latitude 5500 | E2: 10.0.19045.5854 | F2: Capable | G2: 10 | H2: thomas.klatte
A3: TWSERBL007 | B3: mdm/mmpc | C3: Dell Inc. | D3: Latitude 5400 | E3: 10.0.19045.5854 | F3: Capable | G3: 10 | H3: olaf.papke
A4: TWSERBL105 | B4: mdm/mmpc | C4: Dell Inc. | D4: Latitude 5510 | E4: 10.0.19045.5854 | F4: Capable | G4: 10 | H4: simone.walther
A5: TWSERBL106 | B5: mdm/mmpc | C5: Dell Inc. | D5: Latitude 5410 | E5: 10.0.19045.5854 | F5: Capable | G5: 10 | H5: Yvonne.Bernhard
A6: TWSERBL107 | B6: mdm/mmpc | C6: Dell Inc. | D6: Latitude 5510 | E6: 10.0.19045.5854 | F6: Capable | G6: 10 | H6: Luca.Laudi
A7: TWSERBL108 | B7: mdm/mmpc | C7: Dell Inc. | D7: Latitude 5410 | E7: 10.0.19045.5854 | F7: Capable | G7: 10 | H7: Florian.Grim
A8: TWSERBL111 | B8: mdm/mmpc | C8: Dell Inc. | D8: Latitude 5400 | E8: 10.0.19045.5854 | F8: Capable | G8: 10 | H8: Michael.Weinzierl
A9: TWSERBL130V8D3 | B9: mdm/mmpc | C9: Dell Inc. | D9: Latitude 5420 | E9: 10.0.19045.5854 | F9: Capable | G9: 10 | H9: Jens.Steinhardt
A10: TWSERBL154 | B10: mdm/mmpc | C10: Dell Inc. | D10: Latitude 5400 | E10: 10.0.19045.5854 | F10: Capable | G10: 10 | H10: christopher.loew
A11: TWSERBL156 | B11: mdm/mmpc | C11: Dell Inc. | D11: Latitude 7490 | E11: 10.0.19045.5854 | F11: Capable | G11: 10 | H11: baerbel.bretzlaff
A12: TWSERBL157 | B12: mdm/mmpc | C12: Dell Inc. | D12: Latitude 7490 | E12: 10.0.19045.5854 | F12: Capable | G12: 10 | H12: birgit.wolf
... A16: TWSERBL26KCPL3 | B16: mdm/mmpc | C16: Dell Inc. | D16: Latitude 5520 | E16: 10.0.19045.5854 | F16: Capable | G16: 10 | H16: Selina.Zacher
A17: TWSERBL3TKC1F3 | B17: mdm/mmpc | C17: Dell Inc. | D17: Latitude 5420 | E17: 10.0.19045.5854 | F17: Capable | G17: 10 | H17: 0
A18: TWSERBL54JPGY3 | B18: mdm/mmpc | C18: Dell Inc. | D18: Latitude 5440 | E18: 10.0.19045.5854 | F18: Capable | G18: 10 | H18: sandra.juhasz
A19: TWSERBL54MG034 | B19: mdm/mmpc | C19: Dell Inc. | D19: Latitude 5440 | E19: 10.0.19045.5854 | F19: Capable | G19: 10 | H19: andreas.kimmerle
A20: TWSERBL5NGVFB3 | B20: mdm/mmpc | C20: Dell Inc. | D20: Latitude 5410 | E20: 10.0.19045.5854 | F20: Capable | G20: 10 | H20: sandra.hallstein
A21: TWSERBL61JL2T3 | B21: mdm/mmpc | C21: Dell Inc. | D21: Latitude 5430 | E21: 10.0.19045.5854 | F21: Capable | G21: 10 | H21: elmar.burkhardt
A22: TWSERBL6NK1JL3 | B22: mdm/mmpc | C22: Dell Inc. | D22: Latitude 5520 | E22: 10.0.19045.5854 | F22: Capable | G22: 10 | H22: rolf.christmann
A23: TWSERBL7BLPYM3 | B23: mdm/mmpc | C23: Dell Inc. | D23: Latitude 5420 | E23: 10.0.19045.5854 | F23: Capable | G23: 10 | H23: maximilian.thurl
A24: TWSERBL8FM1ML3 | B24: mdm/mmpc | C24: Dell Inc. | D24: Latitude 5520 | E24: 10.0.19045.5854 | F24: Capable | G24: 10 | H24: milos.odavic
A25: TWSERBL9FM1ML3 | B25: mdm/mmpc | C25: Dell Inc. | D25: Latitude 5520 | E25: 10.0.19045.5854 | F25: Capable | G25: 10 | H25: Franziska.Dlouhy
A26: TWSERBLBGZDXL3 | B26: mdm/mmpc | C26: Dell Inc. | D26: Latitude 5530 | E26: 10.0.19045.5854 | F26: Capable | G26: 10 | H26: Kimberly.klingelhoef
A27: TWSERBLBYSX0T3 | B27: mdm/mmpc | C27: Dell Inc. | D27: Latitude 7330 | E27: 10.0.19045.5854 | F27: Capable | G27: 10 | H27: anton.stoynev
A28: TWSERBLDJNG224 | B28: mdm/mmpc | C28: Dell Inc. | D28: Latitude 5540 | E28: 10.0.19045.5854 | F28: Capable | G28: 10 | H28: antonia.Palermo
A29: TWSERBLF3SW7S3 | B29: mdm/mmpc | C29: Dell Inc. | D29: Latitude 5530 | E29: 10.0.19045.5854 | F29: Capable | G29: 10 | H29: Annika.Tesche
... A32: TWSERBLG5JL2T3 | B32: mdm/mmpc | C32: Dell Inc. | D32: Latitude 5430 | E32: 10.0.19045.5854 | F32: Capable | G32: 10 | H32: christian.neumann
A33: TWSERBLG6MG034 | B33: mdm/mmpc | C33: Dell Inc. | D33: Latitude 5440 | E33: 10.0.19045.5854 | F33: Capable | G33: 10 | H33: 0
A34: TWSERBLH41H034 | B34: mdm/mmpc | C34: Dell Inc. | D34: Latitude 5440 | E34: 10.0.19045.5854 | F34: Capable | G34: 10 | H34: Steffen.Schoeppe
A35: TWSERBLH6VBPL3 | B35: mdm/mmpc | C35: Dell Inc. | D35: Latitude 5520 | E35: 10.0.19045.5854 | F35: Capable | G35: 10 | H35: Astrid.Kepper
A36: TWSERBLJJF66J3 | B36: mdm/mmpc | C36: Dell Inc. | D36: Latitude 5420 | E36: 10.0.19045.5854 | F36: Capable | G36: 10 | H36: Thomas.Lorenz

Sheet WIL
A1: TWSWILL005 | B1: mdm/mmpc | C1: Dell Inc. | D1: Latitude 5400 | E1: 10.0.19045.5854 | F1: Capable | G1: 10 | H1: Christian.Lorenz
A2: TWSWILL006 | B2: mdm/mmpc | C2: Dell Inc. | D2: Latitude 7490 | E2: 10.0.19045.5854 | F2: Capable | G2: 10 | H2: Karl.Gaisrucker
A3: TWSWILL2NQ6LX3 | B3: mdm/mmpc | C3: Dell Inc. | D3: Latitude 5540 | E3: 10.0.19045.5854 | F3: Capable | G3: 10 | H3: Michaela.Endemann
A4: TWSWILL4DWY4X3 | B4: mdm/mmpc | C4: Dell Inc. | D4: Latitude 5430 | E4: 10.0.19045.5854 | F4: Capable | G4: 10 | H4: Christian.Keip
A5: TWSWILL6G5KRQ3 | B5: mdm/mmpc | C5: Dell Inc. | D5: Latitude 5430 | E5: 10.0.19045.5854 | F5: Capable | G5: 10 | H5: joergen.scholl
A6: TWSWILLC9Q6GY3 | B6: mdm/mmpc | C6: Dell Inc. | D6: Latitude 5440 | E6: 10.0.19045.5854 | F6: Capable | G6: 10 | H6: Alexander.Wolf
A7: TWSWILLFDZDXL3 | B7: mdm/mmpc | C7: Dell Inc. | D7: Latitude 5530 | E7: 10.0.19045.5854 | F7: Capable | G7: 10 | H7: michael.schumacher
A8: TWSWILLFKXJHX3 | B8: mdm/mmpc | C8: Dell Inc. | D8: Latitude 5540 | E8: 10.0.19045.5854 | F8: Capable | G8: 10 | H8: martina.schmidt
A9: TWSWILLFXQHR73 | B9: mdm/mmpc | C9: Dell Inc. | D9: Latitude 5510 | E9: 10.0.19045.5854 | F9: Capable | G9: 10 | H9: thomas.klemisch
A10: TWSWILLG1MM6M3 | B10: mdm/mmpc | C10: Dell Inc. | D10: Latitude 5420 | E10: 10.0.19045.5854 | F10: Capable | G10: 10 | H10: sigrid.vinnbruck
A11: TWSWILLGDZDXL3 | B11: mdm/mmpc | C11: Dell Inc. | D11: Latitude 5530 | E11: 10.0.19045.5854 | F11: Capable | G11: 10 | H11: marian.gbur
A12: TWSWILLHDZDXL3 | B12: mdm/mmpc | C12: Dell Inc. | D12: Latitude 5530 | E12: 10.0.19045.5854 | F12: Capable | G12: 10 | H12: jessica.rakonic
A13: TWSWILLJDZDXL3 | B13: mdm/mmpc | C13: Dell Inc. | D13: Latitude 5530 | E13: 10.0.19045.5854 | F13: Capable | G13: 10 | H13: ines.strathen
